Workbook

Sheet Dashboard
A1: ALM DASHBOARD — GAP ANALYSIS
A2: =Assumptions!B2 -> Sample National Bank | E2: Report Date: | F2: =Assumptions!B3 -> 45747 | I2: Currency: | J2: =Assumptions!B4 -> USD ($mm)
A4: KEY RISK METRICS
A5: Metric | B5: Value | C5: Threshold | D5: Status | E5: Risk Level
A6: Total Assets ($mm) | B6: =Assumptions!B13 -> 95000 | E6: —
A7: Short-Term Gap (≤3M) / Total Assets | B7: =('Liquidity Gap'!B22+'Liquidity Gap'!C21+'Liquidity Gap'!D21)/'Liquidity Gap'!J10 -> -0.046315789 | C7: > -10% | D7: =IF(B7>-0.1,"PASS","BREACH") -> PASS | E7: =IF(B7>0,"✅ Low",IF(B7>-0.1,"⚠️ Medium","❌ High")) -> ⚠️ Medium
A8: Cumulative 1-Year Gap / Total Assets | B8: ='Liquidity Gap'!F22/'Liquidity Gap'!J10 -> -0.064210526 | C8: > -15% | D8: =IF(B8>-0.15,"PASS","BREACH") -> PASS | E8: =IF(B8>0,"✅ Low",IF(B8>-0.15,"⚠️ Medium","❌ High")) -> ⚠️ Medium
A9: RSA / RSL Ratio (1-Year) | B9: =SUM('Rate Sensitivity Gap'!B10:F10)/SUM('Rate Sensitivity Gap'!B17:F17) -> 1.0639432 | C9: 0.80x - 1.20x | D9: =IF(AND(B9>=0.8,B9<=1.2),"PASS","BREACH") -> PASS | E9: =IF(AND(B9>=0.9,B9<=1.1),"✅ Low",IF(AND(B9>=0.8,B9<=1.2),"⚠️ Medium","❌ High")) -> ✅ Low
A10: NII at Risk (+200 bps) / Equity | B10: ='Rate Sensitivity Gap'!D30 -> 0.0045 | C10: < 5.0% | D10: =IF(ABS(B10)<=0.05,"PASS","BREACH") -> PASS | E10: =IF(ABS(B10)<=0.02,"✅ Low",IF(ABS(B10)<=0.05,"⚠️ Medium","❌ High")) -> ✅ Low
A11: NII at Risk (+200 bps) / Base NII | B11: ='Rate Sensitivity Gap'!C30 -> 0.023958073 | C11: < 10.0% | D11: =IF(ABS(B11)<=0.1,"PASS","BREACH") -> PASS | E11: =IF(ABS(B11)<=0.05,"✅ Low",IF(ABS(B11)<=0.1,"⚠️ Medium","❌ High")) -> ✅ Low
A12: Estimated Base NII ($mm) | B12: ='Rate Sensitivity Gap'!B28 -> 3005.25 | E12: —
A13: Net Interest Margin (NIM) | B13: =B12/B6 -> 0.031634211 | C13: > 2.00% | D13: =IF(B13>=0.02,"PASS","BREACH") -> PASS | E13: =IF(B13>=0.03,"✅ Low",IF(B13>=0.02,"⚠️ Medium","❌ High")) -> ✅ Low
A15: LIQUIDITY GAP PROFILE
A16: Time Bucket | B16: 1-14D | C16: 15-28D | D16: 29D-3M | E16: 3-6M | F16: 6M-1Y | G16: 1-3Y | H16: 3-5Y | I16: >5Y
A17: Total Assets | B17: ='Liquidity Gap'!B10 -> 11000 | C17: ='Liquidity Gap'!C10 -> 6500 | D17: ='Liquidity Gap'!D10 -> 9700 | E17: ='Liquidity Gap'!E10 -> 11000 | F17: ='Liquidity Gap'!F10 -> 13200 | G17: ='Liquidity Gap'!G10 -> 19600 | H17: ='Liquidity Gap'!H10 -> 13000 | I17: ='Liquidity Gap'!I10 -> 11000
A18: Total Liabilities | B18: ='Liquidity Gap'!B18 -> 9700 | C18: ='Liquidity Gap'!C18 -> 8300 | D18: ='Liquidity Gap'!D18 -> 13600 | E18: ='Liquidity Gap'!E18 -> 12700 | F18: ='Liquidity Gap'!F18 -> 13200 | G18: ='Liquidity Gap'!G18 -> 12200 | H18: ='Liquidity Gap'!H18 -> 5200 | I18: ='Liquidity Gap'!I18 -> 20100
A19: Periodic Gap | B19: ='Liquidity Gap'!B21 -> 1300 | C19: ='Liquidity Gap'!C21 -> -1800 | D19: ='Liquidity Gap'!D21 -> -3900 | E19: ='Liquidity Gap'!E21 -> -1700 | F19: ='Liquidity Gap'!F21 -> 0 | G19: ='Liquidity Gap'!G21 -> 7400 | H19: ='Liquidity Gap'!H21 -> 7800 | I19: ='Liquidity Gap'!I21 -> -9100
A20: Cumulative Gap | B20: ='Liquidity Gap'!B22 -> 1300 | C20: ='Liquidity Gap'!C22 -> -500 | D20: ='Liquidity Gap'!D22 -> -4400 | E20: ='Liquidity Gap'!E22 -> -6100 | F20: ='Liquidity Gap'!F22 -> -6100 | G20: ='Liquidity Gap'!G22 -> 1300 | H20: ='Liquidity Gap'!H22 -> 9100 | I20: ='Liquidity Gap'!I22 -> 0
A22: RATE SENSITIVITY GAP PROFILE
A23: Time Bucket | B23: 1-14D | C23: 15-28D | D23: 29D-3M | E23: 3-6M | F23: 6M-1Y | G23: 1-3Y | H23: 3-5Y | I23: >5Y
A24: RSA | B24: ='Rate Sensitivity Gap'!B10 -> 13000 | C24: ='Rate Sensitivity Gap'!C10 -> 7000 | D24: ='Rate Sensitivity Gap'!D10 -> 15200 | E24: ='Rate Sensitivity Gap'!E10 -> 12000 | F24: ='Rate Sensitivity Gap'!F10 -> 12700 | G24: ='Rate Sensitivity Gap'!G10 -> 15100 | H24: ='Rate Sensitivity Gap'!H10 -> 8500 | I24: ='Rate Sensitivity Gap'!I10 -> 7500
A25: RSL | B25: ='Rate Sensitivity Gap'!B17 -> 9500 | C25: ='Rate Sensitivity Gap'!C17 -> 8000 | D25: ='Rate Sensitivity Gap'!D17 -> 13400 | E25: ='Rate Sensitivity Gap'!E17 -> 12400 | F25: ='Rate Sensitivity Gap'!F17 -> 13000 | G25: ='Rate Sensitivity Gap'!G17 -> 11900 | H25: ='Rate Sensitivity Gap'!H17 -> 4900 | I25: ='Rate Sensitivity Gap'!I17 -> 3800
A26: Rate Gap | B26: ='Rate Sensitivity Gap'!B20 -> 3500 | C26: ='Rate Sensitivity Gap'!C20 -> -1000 | D26: ='Rate Sensitivity Gap'!D20 -> 1800 | E26: ='Rate Sensitivity Gap'!E20 -> -400 | F26: ='Rate Sensitivity Gap'!F20 -> -300 | G26: ='Rate Sensitivity Gap'!G20 -> 3200 | H26: ='Rate Sensitivity Gap'!H20 -> 3600 | I26: ='Rate Sensitivity Gap'!I20 -> 3700
A63: NII IMPACT BY RATE SCENARIO
A64: Scenario | B64: NII Impact ($mm) | C64: % of Base NII | D64: % of Equity
A65: +200 bps | B65: ='Rate Sensitivity Gap'!B30 -> 72 | C65: ='Rate Sensitivity Gap'!C30 -> 0.023958073 | D65: ='Rate Sensitivity Gap'!D30 -> 0.0045
A66: +100 bps | B66: ='Rate Sensitivity Gap'!B31 -> 36 | C66: ='Rate Sensitivity Gap'!C31 -> 0.011979037 | D66: ='Rate Sensitivity Gap'!D31 -> 0.00225
A67: Base Case | B67: 0 | C67: 0 | D67: 0
A68: -100 bps | B68: ='Rate Sensitivity Gap'!B33 -> -36 | C68: ='Rate Sensitivity Gap'!C33 -> -0.011979037 | D68: ='Rate Sensitivity Gap'!D33 -> -0.00225
A69: -200 bps | B69: ='Rate Sensitivity Gap'!B34 -> -72 | C69: ='Rate Sensitivity Gap'!C34 -> -0.023958073 | D69: ='Rate Sensitivity Gap'!D34 -> -0.0045
A71: KEY OBSERVATIONS & RISK ASSESSMENT
A72: Liquidity Risk: | B72: Negative short-term gaps (1-14D to 3-6M) indicate outflows exceed inflows — the bank relies on rolling funding or new deposits. Positive gaps in 1-3Y and 3-5Y buckets show long-term asset concentration. Monitor cumulative gap closely; it reaches -$6.1B at the 6M-1Y mark.
A73: Interest Rate Risk: | B73: The bank is ASSET-SENSITIVE (positive rate gap within 1-year horizon of $3.6B). Rising rates INCREASE NII (+$72mm for +200bps). Falling rates DECREASE NII. RSA/RSL ratio of 1.06x is within prudent limits. NII at Risk is well below the 5% of equity threshold.
A74: Overall Position: | B74: All key risk metrics are within regulatory thresholds (PASS). The bank's ALM position is moderately balanced with manageable liquidity and interest rate risk. Recommend monitoring the short-term cumulative gap and maintaining adequate liquidity buffers.

Sheet Assumptions
A1: ASSET LIABILITY MANAGEMENT — KEY ASSUMPTIONS
A2: Bank Name: | B2: Sample National Bank
A3: Reporting Date: | B3: 45747
A4: Currency: | B4: USD ($mm)
A6: BALANCE SHEET SUMMARY
A7: Total Assets | B7: Amount ($mm) | C7: % of Total
A8: Cash & Balances with Central Bank | B8: 8500 | C8: =B8/B$13 -> 0.089473684
A9: Government Securities | B9: 22000 | C9: =B9/B$13 -> 0.23157895
A10: Loans & Advances | B10: 55000 | C10: =B10/B$13 -> 0.57894737
A11: Interbank Placements | B11: 6000 | C11: =B11/B$13 -> 0.063157895
A12: Fixed Assets & Others | B12: 3500 | C12: =B12/B$13 -> 0.036842105
A13: Total Assets | B13: =SUM(B8:B12) -> 95000 | C13: =SUM(C8:C12) -> 1
A15: Total Liabilities & Equity
A16: Demand Deposits (CASA) | B16: 28000 | C16: =B16/B$21 -> 0.29473684
A17: Term Deposits | B17: 35000 | C17: =B17/B$21 -> 0.36842105
A18: Borrowings (Interbank) | B18: 12000 | C18: =B18/B$21 -> 0.12631579
A19: Other Liabilities | B19: 4000 | C19: =B19/B$21 -> 0.042105263
A20: Shareholders' Equity | B20: 16000 | C20: =B20/B$21 -> 0.16842105
A21: Total Liabilities & Equity | B21: =SUM(B16:B20) -> 95000 | C21: =SUM(C16:C20) -> 1
A23: INTEREST RATE ASSUMPTIONS
A24: Asset / Liability Category | B24: Current Rate | C24: Rate Type | D24: Repricing Freq.
A25: Asset Rates
A26: Cash & Central Bank Balances | B26: 0.04 | C26: Fixed | D26: Overnight
A27: Government Securities | B27: 0.065 | C27: Fixed | D27: At Maturity
A28: Loans & Advances (Fixed) | B28: 0.0875 | C28: Fixed | D28: At Maturity
A29: Loans & Advances (Floating) | B29: 0.092 | C29: Floating | D29: Quarterly
A30: Interbank Placements | B30: 0.055 | C30: Fixed | D30: Monthly
A32: Liability Rates
A33: Demand Deposits (CASA) | B33: 0.035 | C33: Floating | D33: Discretionary
A34: Term Deposits | B34: 0.065 | C34: Fixed | D34: At Maturity
A35: Borrowings (Interbank) | B35: 0.058 | C35: Floating | D35: Monthly
A36: Other Liabilities | B36: 0.02 | C36: Fixed | D36: N/A
A38: RATE SHOCK SCENARIOS
A39: Scenario | B39: Rate Change (bps) | C39: Rate Change (%)
A40: Parallel Up (+200 bps) | B40: 200 | C40: =B40/10000 -> 0.02
A41: Parallel Up (+100 bps) | B41: 100 | C41: =B41/10000 -> 0.01
A42: Base Case | B42: 0 | C42: =B42/10000 -> 0
A43: Parallel Down (-100 bps) | B43: -100 | C43: =B43/10000 -> -0.01
A44: Parallel Down (-200 bps) | B44: -200 | C44: =B44/10000 -> -0.02

Sheet Liquidity Gap
A1: LIQUIDITY GAP ANALYSIS (STRUCTURAL)
A2: Maturity Profile of Assets & Liabilities | B2: =Assumptions!B3 -> 45747
A4: ASSETS ($mm) | B4: 1-14 Days | C4: 15-28 Days | D4: 29D-3M | E4: 3-6 Months | F4: 6M-1 Year | G4: 1-3 Years | H4: 3-5 Years | I4: Over 5 Years | J4: Total
A5: Cash & Central Bank | B5: 5500 | C5: 1500 | D5: 1000 | E5: 500 | F5: 0 | G5: 0 | H5: 0 | I5: 0 | J5: =SUM(B5:I5) -> 8500
A6: Government Securities | B6: 1000 | C6: 1000 | D6: 2500 | E6: 3000 | F6: 4000 | G6: 5500 | H6: 3000 | I6: 2000 | J6: =SUM(B6:I6) -> 22000
A7: Loans & Advances | B7: 2000 | C7: 2500 | D7: 5000 | E7: 7000 | F7: 9000 | G7: 14000 | H7: 9500 | I7: 6000 | J7: =SUM(B7:I7) -> 55000
A8: Interbank Placements | B8: 2500 | C8: 1500 | D8: 1200 | E8: 500 | F8: 200 | G8: 100 | H8: 0 | I8: 0 | J8: =SUM(B8:I8) -> 6000
A9: Fixed Assets & Others | B9: 0 | C9: 0 | D9: 0 | E9: 0 | F9: 0 | G9: 0 | H9: 500 | I9: 3000 | J9: =SUM(B9:I9) -> 3500
A10: TOTAL ASSETS | B10: =SUM(B5:B9) -> 11000 | C10: =SUM(C5:C9) -> 6500 | D10: =SUM(D5:D9) -> 9700 | E10: =SUM(E5:E9) -> 11000 | F10: =SUM(F5:F9) -> 13200 | G10: =SUM(G5:G9) -> 19600 | H10: =SUM(H5:H9) -> 13000 | I10: =SUM(I5:I9) -> 11000 | J10: =SUM(J5:J9) -> 95000
A12: LIABILITIES & EQUITY ($mm) | B12: 1-14 Days | C12: 15-28 Days | D12: 29D-3M | E12: 3-6 Months | F12: 6M-1 Year | G12: 1-3 Years | H12: 3-5 Years | I12: Over 5 Years | J12: Total
A13: Demand Deposits (CASA) | B13: 4200 | C13: 2800 | D13: 5600 | E13: 4200 | F13: 4200 | G13: 4200 | H13: 1400 | I13: 1400 | J13: =SUM(B13:I13) -> 28000
A14: Term Deposits | B14: 2000 | C14: 2500 | D14: 5000 | E14: 6000 | F14: 7500 | G14: 7000 | H14: 3000 | I14: 2000 | J14: =SUM(B14:I14) -> 35000
A15: Borrowings (Interbank) | B15: 3000 | C15: 2500 | D15: 2500 | E15: 2000 | F15: 1000 | G15: 500 | H15: 300 | I15: 200 | J15: =SUM(B15:I15) -> 12000
A16: Other Liabilities | B16: 500 | C16: 500 | D16: 500 | E16: 500 | F16: 500 | G16: 500 | H16: 500 | I16: 500 | J16: =SUM(B16:I16) -> 4000
A17: Shareholders' Equity | B17: 0 | C17: 0 | D17: 0 | E17: 0 | F17: 0 | G17: 0 | H17: 0 | I17: 16000 | J17: =SUM(B17:I17) -> 16000
A18: TOTAL LIABILITIES & EQUITY | B18: =SUM(B13:B17) -> 9700 | C18: =SUM(C13:C17) -> 8300 | D18: =SUM(D13:D17) -> 13600 | E18: =SUM(E13:E17) -> 12700 | F18: =SUM(F13:F17) -> 13200 | G18: =SUM(G13:G17) -> 12200 | H18: =SUM(H13:H17) -> 5200 | I18: =SUM(I13:I17) -> 20100 | J18: =SUM(J13:J17) -> 95000
A20: GAP ANALYSIS | B20: 1-14 Days | C20: 15-28 Days | D20: 29D-3M | E20: 3-6 Months | F20: 6M-1 Year | G20: 1-3 Years | H20: 3-5 Years | I20: Over 5 Years | J20: Total
A21: Periodic Gap | B21: =B10-B18 -> 1300 | C21: =C10-C18 -> -1800 | D21: =D10-D18 -> -3900 | E21: =E10-E18 -> -1700 | F21: =F10-F18 -> 0 | G21: =G10-G18 -> 7400 | H21: =H10-H18 -> 7800 | I21: =I10-I18 -> -9100 | J21: =J10-J18 -> 0
A22: Cumulative Gap | B22: =B21 -> 1300 | C22: =B22+C21 -> -500 | D22: =C22+D21 -> -4400 | E22: =D22+E21 -> -6100 | F22: =E22+F21 -> -6100 | G22: =F22+G21 -> 1300 | H22: =G22+H21 -> 9100 | I22: =H22+I21 -> 0 | J22: =I22 -> 0
A23: Gap as % of Total Assets | B23: =B21/J$10 -> 0.013684211 | C23: =C21/J$10 -> -0.018947368 | D23: =D21/J$10 -> -0.041052632 | E23: =E21/J$10 -> -0.017894737 | F23: =F21/J$10 -> 0 | G23: =G21/J$10 -> 0.077894737 | H23: =H21/J$10 -> 0.082105263 | I23: =I21/J$10 -> -0.095789474 | J23: =J21/J$10 -> 0
A24: Cumulative Gap as % of Total Assets | B24: =B22/J$10 -> 0.013684211 | C24: =C22/J$10 -> -0.0052631579 | D24: =D22/J$10 -> -0.046315789 | E24: =E22/J$10 -> -0.064210526 | F24: =F22/J$10 -> -0.064210526 | G24: =G22/J$10 -> 0.013684211 | H24: =H22/J$10 -> 0.095789474 | I24: =I22/J$10 -> 0 | J24: =J22/J$10 -> 0
A25: Gap as % of Total Outflows | B25: =IF(B18=0,"-",B21/B18) -> 0.13402062 | C25: =IF(C18=0,"-",C21/C18) -> -0.21686747 | D25: =IF(D18=0,"-",D21/D18) -> -0.28676471 | E25: =IF(E18=0,"-",E21/E18) -> -0.13385827 | F25: =IF(F18=0,"-",F21/F18) -> 0 | G25: =IF(G18=0,"-",G21/G18) -> 0.60655738 | H25: =IF(H18=0,"-",H21/H18) -> 1.5 | I25: =IF(I18=0,"-",I21/I18) -> -0.45273632 | J25: =IF(J18=0,"-",J21/J18) -> 0

Sheet Rate Sensitivity Gap
A1: INTEREST RATE SENSITIVITY GAP ANALYSIS
A2: Rate-Sensitive Assets vs Rate-Sensitive Liabilities | B2: =Assumptions!B3 -> 45747
A4: RATE-SENSITIVE ASSETS ($mm) | B4: 1-14 Days | C4: 15-28 Days | D4: 29D-3M | E4: 3-6 Months | F4: 6M-1 Year | G4: 1-3 Years | H4: 3-5 Years | I4: Over 5 Years | J4: Total
A5: Cash & Central Bank (O/N rate) | B5: 5500 | C5: 1500 | D5: 1000 | E5: 0 | F5: 0 | G5: 0 | H5: 0 | I5: 0 | J5: =SUM(B5:I5) -> 8000
A6: Govt Securities (Maturing) | B6: 1000 | C6: 1000 | D6: 2500 | E6: 3000 | F6: 4000 | G6: 5500 | H6: 3000 | I6: 2000 | J6: =SUM(B6:I6) -> 22000
A7: Loans - Floating Rate (Repricing) | B7: 3500 | C7: 2000 | D7: 8000 | E7: 5500 | F7: 4000 | G7: 3000 | H7: 1500 | I7: 500 | J7: =SUM(B7:I7) -> 28000
A8: Loans - Fixed Rate (Maturing) | B8: 500 | C8: 1000 | D8: 2500 | E8: 3000 | F8: 4500 | G8: 6500 | H8: 4000 | I8: 5000 | J8: =SUM(B8:I8) -> 27000
A9: Interbank Placements | B9: 2500 | C9: 1500 | D9: 1200 | E9: 500 | F9: 200 | G9: 100 | H9: 0 | I9: 0 | J9: =SUM(B9:I9) -> 6000
A10: TOTAL RSA | B10: =SUM(B5:B9) -> 13000 | C10: =SUM(C5:C9) -> 7000 | D10: =SUM(D5:D9) -> 15200 | E10: =SUM(E5:E9) -> 12000 | F10: =SUM(F5:F9) -> 12700 | G10: =SUM(G5:G9) -> 15100 | H10: =SUM(H5:H9) -> 8500 | I10: =SUM(I5:I9) -> 7500 | J10: =SUM(J5:J9) -> 91000
A12: RATE-SENSITIVE LIABILITIES ($mm) | B12: 1-14 Days | C12: 15-28 Days | D12: 29D-3M | E12: 3-6 Months | F12: 6M-1 Year | G12: 1-3 Years | H12: 3-5 Years | I12: Over 5 Years | J12: Total
A13: CASA (Repricing - Discretionary) | B13: 4200 | C13: 2800 | D13: 5600 | E13: 4200 | F13: 4200 | G13: 4200 | H13: 1400 | I13: 1400 | J13: =SUM(B13:I13) -> 28000
A14: Term Deposits (Maturing) | B14: 2000 | C14: 2500 | D14: 5000 | E14: 6000 | F14: 7500 | G14: 7000 | H14: 3000 | I14: 2000 | J14: =SUM(B14:I14) -> 35000
A15: Interbank Borrowings (Floating) | B15: 3000 | C15: 2500 | D15: 2500 | E15: 2000 | F15: 1000 | G15: 500 | H15: 300 | I15: 200 | J15: =SUM(B15:I15) -> 12000
A16: Other Rate-Sensitive Liabilities | B16: 300 | C16: 200 | D16: 300 | E16: 200 | F16: 300 | G16: 200 | H16: 200 | I16: 200 | J16: =SUM(B16:I16) -> 1900
A17: TOTAL RSL | B17: =SUM(B13:B16) -> 9500 | C17: =SUM(C13:C16) -> 8000 | D17: =SUM(D13:D16) -> 13400 | E17: =SUM(E13:E16) -> 12400 | F17: =SUM(F13:F16) -> 13000 | G17: =SUM(G13:G16) -> 11900 | H17: =SUM(H13:H16) -> 4900 | I17: =SUM(I13:I16) -> 3800 | J17: =SUM(J13:J16) -> 76900
A19: RATE SENSITIVITY GAP ANALYSIS | B19: 1-14 Days | C19: 15-28 Days | D19: 29D-3M | E19: 3-6 Months | F19: 6M-1 Year | G19: 1-3 Years | H19: 3-5 Years | I19: Over 5 Years | J19: Total
A20: Rate Sensitivity Gap (RSA - RSL) | B20: =B10-B17 -> 3500 | C20: =C10-C17 -> -1000 | D20: =D10-D17 -> 1800 | E20: =E10-E17 -> -400 | F20: =F10-F17 -> -300 | G20: =G10-G17 -> 3200 | H20: =H10-H17 -> 3600 | I20: =I10-I17 -> 3700 | J20: =J10-J17 -> 14100
A21: Cumulative Rate Gap | B21: =B20 -> 3500 | C21: =B21+C20 -> 2500 | D21: =C21+D20 -> 4300 | E21: =D21+E20 -> 3900 | F21: =E21+F20 -> 3600 | G21: =F21+G20 -> 6800 | H21: =G21+H20 -> 10400 | I21: =H21+I20 -> 14100 | J21: =I21 -> 14100
A22: RSA / RSL Ratio | B22: =IF(B17=0,"-",B10/B17) -> 1.3684211 | C22: =IF(C17=0,"-",C10/C17) -> 0.875 | D22: =IF(D17=0,"-",D10/D17) -> 1.1343284 | E22: =IF(E17=0,"-",E10/E17) -> 0.96774194 | F22: =IF(F17=0,"-",F10/F17) -> 0.97692308 | G22: =IF(G17=0,"-",G10/G17) -> 1.2689076 | H22: =IF(H17=0,"-",H10/H17) -> 1.7346939 | I22: =IF(I17=0,"-",I10/I17) -> 1.9736842 | J22: =IF(J17=0,"-",J10/J17) -> 1.183355
A23: Gap as % of Total RSA | B23: =B20/J$10 -> 0.038461538 | C23: =C20/J$10 -> -0.010989011 | D23: =D20/J$10 -> 0.01978022 | E23: =E20/J$10 -> -0.0043956044 | F23: =F20/J$10 -> -0.0032967033 | G23: =G20/J$10 -> 0.035164835 | H23: =H20/J$10 -> 0.03956044 | I23: =I20/J$10 -> 0.040659341 | J23: =J20/J$10 -> 0.15494505
A25: NII IMPACT ANALYSIS (Earnings at Risk)
A26: Cumulative 1-Year Rate Gap: | B26: =SUM(B20:F20) -> 3600
A27: Rate Shock Scenario | B27: Impact on NII ($mm) | C27: % of Base NII | D27: % of Equity
A28: Base NII (Estimated Annual) | B28: =Assumptions!B8*Assumptions!B26+Assumptions!B9*Assumptions!B27+Assumptions!B10*((Assumptions!B28+Assumptions!B29)/2)+Assumptions!B11*Assumptions!B30-Assumptions!B16*Assumptions!B33-Assumptions!B17*Assumptions!B34-Assumptions!B18*Assumptions!B35-Assumptions!B19*Assumptions!B36 -> 3005.25
A30: +200 bps Parallel Shift | B30: =B$26*Assumptions!C40 -> 72 | C30: =B30/B$28 -> 0.023958073 | D30: =B30/Assumptions!B20 -> 0.0045
A31: +100 bps Parallel Shift | B31: =B$26*Assumptions!C41 -> 36 | C31: =B31/B$28 -> 0.011979037 | D31: =B31/Assumptions!B20 -> 0.00225
A32: Base Case (No Change) | B32: 0 | C32: 0 | D32: 0
A33: -100 bps Parallel Shift | B33: =B$26*Assumptions!C43 -> -36 | C33: =B33/B$28 -> -0.011979037 | D33: =B33/Assumptions!B20 -> -0.00225
A34: -200 bps Parallel Shift | B34: =B$26*Assumptions!C44 -> -72 | C34: =B34/B$28 -> -0.023958073 | D34: =B34/Assumptions!B20 -> -0.0045

Sheet ALM Notes & Guide
A1: ALM GAP ANALYSIS — DETAILED NOTES & Q&A GUIDE
A2: Reference guide for understanding the Asset Liability Management Gap Analysis model, key concepts, methodology, and interpretation.
A4: SECTION 1: GENERAL ALM CONCEPTS
A5: Question | B5: Answer | C5: Sheet Reference
A6: Q1. What is Asset Liability Management (ALM)? | B6: ALM is a risk management framework used by banks and financial institutions to manage the risks arising from mismatches between assets and liabilities. It focuses on two primary risks: (1) Liquidity Risk — the risk that maturing liabilities exceed maturing assets in any time period, creating a funding gap; and (2) Interest Rate Risk — the risk that changes in market interest rates adversely affect the bank's net interest income (NII) or economic value of equity (EVE). ALM ensures the bank can meet its obligations while optimizing profitability. | C6: All sheets
A7: Q2. What is a Gap Analysis in ALM? | B7: Gap Analysis is the foundational ALM tool that compares the maturity (or repricing) profile of assets against liabilities across defined time buckets. The "gap" in each bucket equals Assets minus Liabilities. A POSITIVE gap means assets exceed liabilities (asset-heavy), while a NEGATIVE gap means liabilities exceed assets (liability-heavy). The analysis is performed in two forms: (1) Structural Liquidity Gap — based on contractual maturity, and (2) Interest Rate Sensitivity Gap — based on repricing dates for rate-sensitive items. | C7: Liquidity Gap, Rate Sensitivity Gap
A8: Q3. What are the standard RBI/Basel time buckets used? | B8: This model uses the 8 standard maturity buckets prescribed by RBI (Reserve Bank of India) and aligned with Basel III guidelines: (1) 1-14 Days, (2) 15-28 Days, (3) 29 Days to 3 Months, (4) 3-6 Months, (5) 6 Months to 1 Year, (6) 1-3 Years, (7) 3-5 Years, (8) Over 5 Years. These buckets capture short-term liquidity exposure (buckets 1-3), medium-term funding gaps (buckets 4-5), and long-term structural mismatches (buckets 6-8). | C8: Liquidity Gap Row 4, Rate Sensitivity Gap Row 4
A9: Q4. Why is ALM important for banks? | B9: Banks inherently borrow short (deposits) and lend long (loans/mortgages), creating a natural maturity mismatch. ALM is critical because: (1) Regulatory compliance — Basel III and local regulators (RBI, OCC, PRA) mandate ALM reporting and limits; (2) Earnings protection — mismatches expose NII to interest rate volatility; (3) Liquidity management — ensures the bank can meet withdrawal demands and maturing obligations; (4) Capital adequacy — EVE impact of rate changes affects economic capital; (5) Strategic planning — informs asset/liability mix, pricing decisions, and funding strategies. | C9: Dashboard (Key Risk Metrics)
A11: SECTION 2: LIQUIDITY GAP ANALYSIS
A12: Question | B12: Answer | C12: Sheet Reference
A13: Q5. What is the Structural Liquidity Gap? | B13: The Structural Liquidity Gap (also called Maturity Gap) shows the difference between assets and liabilities maturing in each time bucket based on contractual maturity. Formula: Periodic Gap = Total Assets Maturing – Total Liabilities Maturing in each bucket. A negative gap indicates a net cash outflow — the bank needs to raise funds or roll over maturing liabilities. In this model, assets include cash, government securities, loans, interbank placements, and fixed assets distributed by their maturity profiles. | C13: Liquidity Gap, Rows 5-10 (Assets), Rows 13-18 (Liabilities), Row 21 (Gap)
A14: Q6. What is the Periodic Gap vs. Cumulative Gap? | B14: PERIODIC GAP: The net difference between assets and liabilities maturing within a SINGLE time bucket. It shows the funding surplus or deficit for that specific period. CUMULATIVE GAP: The running total of all periodic gaps from the first bucket to the current bucket. Formula: Cumulative Gap(t) = Cumulative Gap(t-1) + Periodic Gap(t). The cumulative gap is more important for risk assessment because it shows the bank's total net funding position up to each point in time. A persistently negative cumulative gap signals structural funding dependency. | C14: Liquidity Gap, Row 21 (Periodic), Row 22 (Cumulative)
A15: Q7. How should the Liquidity Gap ratios be interpreted? | B15: Three key ratios are calculated: (1) Gap as % of Total Assets = Periodic Gap / Total Assets — shows relative size of the mismatch vs. the bank's balance sheet; typically should stay within ±10%. (2) Cumulative Gap as % of Total Assets = Cumulative Gap / Total Assets — the most watched metric; RBI guideline suggests not exceeding -15% for the 1-year cumulative bucket. (3) Gap as % of Total Outflows = Periodic Gap / Total Liabilities in bucket — shows how much of the outflow is uncovered; a ratio of -30% means 30% of outflows in that bucket lack matching asset maturities. | C15: Liquidity Gap, Rows 23-25
A16: Q8. Why do some buckets show negative gaps while others are positive? | B16: This is the natural consequence of bank business models. Short-term buckets (1-14D through 3-6M) typically show negative gaps because: (a) Deposits (especially demand deposits/CASA) are classified in short-term buckets as they can be withdrawn anytime, (b) A large portion of loans have longer maturities (1-5+ years). Long-term buckets (1-3Y, 3-5Y) show positive gaps because the bulk of loan portfolios mature in these tenors. This "borrow short, lend long" pattern is how banks earn the term premium but creates liquidity risk. | C16: Liquidity Gap, Row 21 (see conditional formatting)
A17: Q9. What does it mean when cumulative gap reaches ($6,100) at the 6M-1Y bucket? | B17: The cumulative gap of ($6,100)mm at the 6M-1Y mark means that over the next 12 months, the bank's maturing liabilities exceed maturing assets by $6.1 billion. This represents 6.4% of total assets ($6,100 / $95,000). The bank must fund this gap through: (1) New deposit acquisition, (2) Rolling over maturing term deposits, (3) Interbank borrowing, (4) Selling/repo-ing liquid securities, or (5) Central bank facilities. While within regulatory limits (<15%), it requires active liquidity management and contingency planning. | C17: Liquidity Gap F22; Dashboard B8
A18: Q10. How are asset categories distributed across maturity buckets? | B18: Each asset class has a characteristic maturity profile: CASH & CENTRAL BANK ($8.5B) — concentrated in shortest buckets (1-14D: $5.5B) as these are highly liquid overnight balances. GOVT SECURITIES ($22B) — spread across all buckets with concentration in medium-term (6M-3Y) reflecting a laddered investment portfolio. LOANS ($55B) — heaviest in 1-3Y ($14B) and 3-5Y ($9.5B) buckets, reflecting typical loan tenors. INTERBANK ($6B) — concentrated in short-term buckets (mostly <3M) as these are typically short-dated placements. FIXED ASSETS ($3.5B) — placed in the longest bucket (>5Y) as they are non-maturing. | C18: Liquidity Gap, Rows 5-9
A20: SECTION 3: INTEREST RATE SENSITIVITY GAP
A21: Question | B21: Answer | C21: Sheet Reference
A22: Q11. What is the difference between Liquidity Gap and Rate Sensitivity Gap? | B22: LIQUIDITY GAP classifies ALL assets and liabilities by their contractual maturity date — when cash flows actually occur. It measures funding risk. RATE SENSITIVITY GAP classifies only RATE-SENSITIVE items by their next repricing date — when the interest rate resets. It measures interest rate risk. Key difference: A 10-year floating-rate loan reprices quarterly, so it appears in the “29D-3M” bucket for rate sensitivity (next repricing) but in the “3-5Y” or “>5Y” bucket for liquidity (contractual maturity). Non-rate-sensitive items (equity, fixed assets, non-interest-bearing deposits) may be excluded from rate sensitivity analysis. | C22: Liquidity Gap vs. Rate Sensitivity Gap
A23: Q12. What are Rate-Sensitive Assets (RSA) and Rate-Sensitive Liabilities (RSL)? | B23: RSA are assets whose interest income changes when market rates change, either because they carry floating rates (repricing at intervals) or because they mature and are reinvested at new rates. In this model: Cash ($8B, overnight rate), Govt Securities ($22B, maturing/reinvested), Floating Loans ($28B, repricing quarterly), Fixed Loans ($27B, maturing), Interbank ($6B, short-term). Total RSA = $91B. RSL are liabilities whose interest cost changes with rate movements: CASA ($28B, discretionary repricing), Term Deposits ($35B, maturing/renewed), Interbank Borrowings ($12B, floating), Other ($1.9B). Total RSL = $76.9B. Equity ($16B) is excluded from RSL as it has no interest cost. | C23: Rate Sensitivity Gap, Rows 5-10 (RSA), Rows 13-17 (RSL)
A24: Q13. What does an RSA/RSL Ratio of 1.06x mean? | B24: The RSA/RSL ratio of 1.06x (within the 1-year horizon) means rate-sensitive assets exceed rate-sensitive liabilities by 6%. This indicates the bank is ASSET-SENSITIVE (also called "positively gapped"). Implications: (1) When rates RISE → asset yields reprice upward faster/more than liability costs → NII INCREASES → beneficial. (2) When rates FALL → asset yields decline faster than funding costs → NII DECREASES → harmful. Prudent range: 0.80x–1.20x. Outside this range, the bank has significant directional rate exposure. At 1.06x, the position is slightly asset-sensitive but well within prudent limits. | C24: Rate Sensitivity Gap Row 22; Dashboard B9
A25: Q14. What is the Cumulative 1-Year Rate Gap and why is it important? | B25: The Cumulative 1-Year Rate Gap ($3,600mm in this model) is the sum of all periodic rate sensitivity gaps within the first 5 time buckets (1-14D through 6M-1Y). It represents the net rate-sensitive position that will reprice within one year. This is the single most important number for NII-at-Risk analysis because: (1) It directly determines how much NII changes for a given rate shock: ΔNII = Cumulative Gap × ΔRate. (2) Regulators focus on the 1-year horizon for earnings risk limits. (3) It captures both maturing fixed-rate and repricing floating-rate exposures. At $3.6B positive, a +100bps rate increase adds approximately $36mm to annual NII. | C25: Rate Sensitivity Gap B26
A26: Q15. How are floating-rate loans different from fixed-rate loans in this analysis? | B26: FLOATING-RATE LOANS ($28B): Classified by their REPRICING DATE, not maturity. A 20-year mortgage on a quarterly floating rate appears in the 29D-3M bucket because the rate resets every quarter. The full principal amount is rate-sensitive in the near-term. These drive most of the bank's rate sensitivity. FIXED-RATE LOANS ($27B): Classified by their MATURITY DATE. The rate is locked until maturity, so they only become rate-sensitive when they mature and must be reinvested. A 5-year fixed loan at 8.75% stays at that rate regardless of market movements. The split between fixed and floating determines how responsive the bank's asset yield is to rate changes. | C26: Rate Sensitivity Gap, Row 7 (Floating) vs. Row 8 (Fixed); Assumptions B28-B29
A27: Q16. Why is CASA (Demand Deposits) classified as rate-sensitive? | B27: CASA deposits ($28B) have a key characteristic: the bank sets the rate at its DISCRETION (not by contract or market benchmark). This makes them rate-sensitive because: (1) Banks typically adjust CASA rates (currently 3.50%) in response to market rate changes, though with a lag and asymmetry — they raise deposit rates slowly when rates rise, and cut quickly when rates fall. (2) In a rising rate environment, CASA represents a funding advantage as repricing is slower than market rates. (3) Behavioral modeling is complex — while contractually on-demand, a portion is considered "core" (stable, non-withdrawable). The distribution across buckets ($4.2B per short-term bucket) reflects assumed behavioral run-off patterns. | C27: Rate Sensitivity Gap Row 13; Assumptions B33
A29: SECTION 4: NII IMPACT & EARNINGS AT RISK
A30: Question | B30: Answer | C30: Sheet Reference
A31: Q17. How is the Base NII ($3,005mm) calculated? | B31: Base NII (Net Interest Income) is estimated as Total Interest Income minus Total Interest Expense using the weighted average rates from the Assumptions sheet. Interest Income = Cash×4.00% + Govt Sec×6.50% + Loans×avg(8.75%,9.20%) + Interbank×5.50% = $8,500×0.04 + $22,000×0.065 + $55,000×0.0898 + $6,000×0.055 = $340 + $1,430 + $4,938 + $330 = $7,038mm. Interest Expense = CASA×3.50% + Term Dep×6.50% + Borrowings×5.80% + Other×2.00% = $980 + $2,275 + $696 + $80 = $4,031mm. Base NII = $7,038 – $4,031 ≈ $3,005mm. This represents the bank's net interest margin of approximately 3.16% ($3,005/$95,000). | C31: Rate Sensitivity Gap B28; Assumptions (Rates)
A32: Q18. How is the NII Impact (Earnings at Risk) calculated? | B32: NII Impact measures how much the bank's Net Interest Income changes under parallel interest rate shock scenarios. The standard formula is: ΔNII = Cumulative 1-Year Rate Gap × Rate Change. For this bank: Cumulative 1-Year Gap = $3,600mm; +200bps shock: ΔNII = $3,600 × 2.00% = +$72mm (NII increases); +100bps shock: ΔNII = $3,600 × 1.00% = +$36mm; -100bps shock: ΔNII = $3,600 × (-1.00%) = -$36mm (NII decreases); -200bps shock: ΔNII = $3,600 × (-2.00%) = -$72mm. This is a simplified linear approximation. In practice, banks use more sophisticated models accounting for optionality (prepayments, caps/floors), basis risk, and non-parallel shifts. | C32: Rate Sensitivity Gap B26, B30:B34; Assumptions B40:B44
A33: Q19. What is the significance of NII at Risk as % of Equity (0.45%)? | B33: NII at Risk as % of Equity measures the maximum potential NII loss relative to the bank's capital base. At 0.45% (for +200bps), this is well within the typical regulatory threshold of <5%. Interpretation: A +200bps rate shock would change NII by $72mm, which is only 0.45% of the bank's $16B equity. This means: (1) The bank's capital can easily absorb the earnings volatility from rate changes; (2) There is substantial headroom before breaching limits; (3) The bank could take on more rate risk if desired for strategic positioning. Banks with this metric >5% are considered to have high interest rate risk and may face regulatory scrutiny. | C33: Rate Sensitivity Gap D30; Dashboard B10
A34: Q20. What does "Parallel Shift" mean in rate shock scenarios? | B34: A parallel shift assumes ALL interest rates across the entire yield curve move by the same amount simultaneously. For example, +200bps parallel shift means: overnight rates increase by 2%, 3-month rates increase by 2%, 1-year rates increase by 2%, 5-year rates increase by 2%, etc. This is a simplification — in reality, rate changes are often non-parallel (short rates may move more than long rates, or vice versa). Advanced ALM models also test: (1) Steepening — short rates unchanged, long rates up; (2) Flattening — short rates up, long rates unchanged; (3) Inversion — short rates rise above long rates; (4) Basis shocks — LIBOR/SOFR spread widens. The ±200bps range aligns with Basel Committee's IRRBB (Interest Rate Risk in the Banking Book) prescribed shock scenarios. | C34: Assumptions B38:C44
A35: Q21. Why is the bank asset-sensitive, and what does that imply for strategy? | B35: The bank is asset-sensitive (positive rate gap of $3.6B within 1 year) primarily because: (1) $28B of floating-rate loans reprice quickly (quarterly), while (2) A significant portion of liabilities are in fixed-rate term deposits ($35B) that only reprice at maturity. STRATEGIC IMPLICATIONS: In a rising rate environment, this position is FAVORABLE — asset yields increase before funding costs catch up. In a falling rate environment, it is UNFAVORABLE — asset yields drop first. If the bank's view is that rates will fall, it may consider: (a) Extending floating-rate loan tenors to fixed, (b) Shifting funding toward floating-rate borrowings, (c) Using interest rate swaps to convert the gap from positive to negative (pay-fixed, receive-floating). | C35: Rate Sensitivity Gap Row 20-21; Dashboard B9
A37: SECTION 5: DASHBOARD METRICS & REGULATORY THRESHOLDS
A38: Question | B38: Answer | C38: Sheet Reference
A39: Q22. What does the Short-Term Gap (≤3M) / Total Assets metric tell us? | B39: This metric (-4.6% in this model) measures the bank's immediate liquidity exposure over the next 3 months. It is the cumulative gap for buckets 1-14D + 15-28D + 29D-3M, divided by total assets. Threshold: > -10% (i.e., the negative gap should not exceed 10% of total assets). At -4.6%, the bank has adequate short-term liquidity but is relying on rolling short-term funding. A breach (below -10%) would indicate severe near-term funding stress and trigger enhanced liquidity management, potential asset sales, or emergency borrowing facilities. | C39: Dashboard B7
A40: Q23. What does the Cumulative 1-Year Gap / Total Assets metric tell us? | B40: This metric (-6.4% in this model) extends the liquidity assessment to the full 1-year horizon. It shows that maturing liabilities exceed maturing assets by $6.1B over 12 months, representing 6.4% of the total balance sheet. Threshold: > -15% (RBI/Basel guideline). At -6.4%, the bank is well within the limit, meaning it has a manageable 1-year funding gap. Action triggers: -10% to -15% = enhanced monitoring and contingency planning; below -15% = regulatory breach requiring immediate remediation (e.g., reducing loan commitments, raising long-term funding, selling assets). | C40: Dashboard B8
A41: Q24. What is the Net Interest Margin (NIM) and is 3.16% good? | B41: NIM = Net Interest Income / Total Assets = $3,005mm / $95,000mm = 3.16%. NIM is the most fundamental profitability metric for banks — it measures how efficiently the bank earns interest on its asset base. Threshold: > 2.00% is the minimum prudent level; most healthy banks target 2.50%-3.50%. At 3.16%, this bank has a healthy NIM indicating: (1) Good spread between asset yields (~7.4% weighted avg) and liability costs (~4.2%), (2) Effective pricing of loans and deposits, (3) Reasonable asset mix with higher-yielding loans forming the majority. NIM can be enhanced by: increasing the loan-to-asset ratio, improving CASA ratio (cheaper funding), or repricing loans upward. | C41: Dashboard B13
A42: Q25. What do the PASS/BREACH indicators mean on the Dashboard? | B42: Each key metric is compared against regulatory or internal prudential thresholds: PASS (green) = Metric is within acceptable limits; no action required. BREACH (red) = Metric has crossed the threshold; requires immediate attention and remediation plan. Risk Levels provide additional granularity: ✅ Low = well within limits, no concern; ⚠️ Medium = within limits but approaching threshold, warrants monitoring; ❌ High = at or near breach level, urgent action needed. Currently all 7 metrics show PASS, with liquidity metrics at Medium risk (approaching but not breaching limits) and interest rate metrics at Low risk. | C42: Dashboard D7:E13
A43: Q26. How should the RSA/RSL Ratio range of 0.80x-1.20x be interpreted? | B43: The RSA/RSL Ratio threshold of 0.80x-1.20x represents the "neutral zone" where the bank's interest rate risk is considered manageable. Breakdown: <0.80x = Heavily liability-sensitive; NII highly vulnerable to rising rates (assets reprice slower than liabilities). Very risky if rates are expected to rise. 0.80x-0.90x = Moderately liability-sensitive; some rate risk but manageable. 0.90x-1.10x = Nearly balanced; minimal directional rate risk (ideal for risk-averse banks). 1.10x-1.20x = Moderately asset-sensitive; benefits from rising rates (this bank at 1.06x). >1.20x = Heavily asset-sensitive; NII highly vulnerable to falling rates. At 1.06x, the bank has a slight asset-sensitive tilt, which is favorable in a rising rate environment. | C43: Dashboard B9, C9
A45: SECTION 6: PRACTICAL USAGE & MODEL ASSUMPTIONS
A46: Question | B46: Answer | C46: Sheet Reference
...

Sheet Illust - Structural Liquidity
A1: ILLUSTRATION: STRUCTURAL LIQUIDITY GAP
A3: CONCEPT
A4: What is it? | B4: The Structural Liquidity Gap places every asset and liability into a time bucket based on its CONTRACTUAL MATURITY — the date the cash flow actually occurs.
A5: Why does it matter? | B5: If more liabilities mature than assets in any period, the bank must find NEW FUNDING to cover the shortfall. This is liquidity risk.
A6: Key formula: | B6: Gap = Assets Maturing – Liabilities Maturing | Positive = Surplus (safe) | Negative = Deficit (risk)
A8: STEP-BY-STEP EXAMPLE: "MINI BANK" (Total Balance Sheet = $1,000)
A9: Step 1: Place each ASSET into its maturity bucket
B10: 0-3 Months | C10: 3-12 Months | D10: 1-5 Years | E10: >5 Years | F10: Total
A11: Cash (available now) | B11: 100 | C11: 0 | D11: 0 | E11: 0 | F11: =SUM(B11:E11) -> 100
A12: Short-Term Bonds (mature in 6M) | B12: 0 | C12: 150 | D12: 0 | E12: 0 | F12: =SUM(B12:E12) -> 150
A13: Business Loans (mature in 3Y) | B13: 0 | C13: 0 | D13: 400 | E13: 0 | F13: =SUM(B13:E13) -> 400
A14: Mortgages (mature in 20Y) | B14: 0 | C14: 0 | D14: 0 | E14: 350 | F14: =SUM(B14:E14) -> 350
A15: → TOTAL ASSETS | B15: =SUM(B11:B14) -> 100 | C15: =SUM(C11:C14) -> 150 | D15: =SUM(D11:D14) -> 400 | E15: =SUM(E11:E14) -> 350 | F15: =SUM(F11:F14) -> 1000
A17: Step 2: Place each LIABILITY into its maturity bucket
B18: 0-3 Months | C18: 3-12 Months | D18: 1-5 Years | E18: >5 Years | F18: Total
A19: Demand Deposits (withdrawable anytime) | B19: 200 | C19: 100 | D19: 0 | E19: 0 | F19: =SUM(B19:E19) -> 300
A20: 1-Year Term Deposits | B20: 0 | C20: 250 | D20: 100 | E20: 0 | F20: =SUM(B20:E20) -> 350
A21: Interbank Borrowing (30-day) | B21: 150 | C21: 0 | D21: 0 | E21: 0 | F21: =SUM(B21:E21) -> 150
A22: Equity (permanent capital) | B22: 0 | C22: 0 | D22: 0 | E22: 200 | F22: =SUM(B22:E22) -> 200
A23: → TOTAL LIABILITIES & EQUITY | B23: =SUM(B19:B22) -> 350 | C23: =SUM(C19:C22) -> 350 | D23: =SUM(D19:D22) -> 100 | E23: =SUM(E19:E22) -> 200 | F23: =SUM(F19:F22) -> 1000
A25: Step 3: Calculate the GAP (Assets – Liabilities) in each bucket
B26: 0-3 Months | C26: 3-12 Months | D26: 1-5 Years | E26: >5 Years | F26: Interpretation
A27: Total Assets (from Step 1) | B27: =B15 -> 100 | C27: =C15 -> 150 | D27: =D15 -> 400 | E27: =E15 -> 350
A28: Total Liabilities (from Step 2) | B28: =B23 -> 350 | C28: =C23 -> 350 | D28: =D23 -> 100 | E28: =E23 -> 200
A29: → GAP = Assets – Liabilities | B29: =B27-B28 -> -250 | C29: =C27-C28 -> -200 | D29: =D27-D28 -> 300 | E29: =E27-E28 -> 150
A31: Step 4: Read the result — What does each gap tell you?
A32: 0-3 Months: Gap = ($250) | B32: ❌ DEFICIT — $350 in liabilities mature but only $100 in assets. The bank must find $250 in new funding within 3 months (e.g., roll over deposits, borrow in interbank market, sell liquid securities).
A33: 3-12 Months: Gap = ($200) | B33: ❌ DEFICIT — Another $200 shortfall. Deposits maturing faster than loans. The bank needs continued funding. Cumulative pressure is building.
A34: 1-5 Years: Gap = $300 | B34: ✅ SURPLUS — $400 in loan repayments vs only $100 in maturing term deposits. The bank receives more cash than it owes. This is where the bank earns its "maturity transformation" premium.
A35: >5 Years: Gap = $150 | B35: ✅ SURPLUS — Mortgage repayments ($350) exceed equity obligations ($200). Long-term assets generating cash flow well beyond funding maturity.
A37: KEY TAKEAWAY
A38: The Pattern: | B38: Banks BORROW SHORT (deposits are short-term) and LEND LONG (loans are long-term). This creates NEGATIVE gaps in short-term buckets and POSITIVE gaps in long-term buckets. This is the fundamental business model of banking — but it creates liquidity risk that must be actively managed.
A39: The Risk: | B39: If depositors withdraw faster than expected, or if the bank cannot roll over maturing borrowings, the short-term deficit becomes a LIQUIDITY CRISIS. This is why regulators require banks to monitor and report structural liquidity gaps, and maintain adequate liquid asset buffers.
A40: Your Model: | B40: See the full analysis with 8 RBI/Basel maturity buckets and actual bank data in the ‘Liquidity Gap’ sheet. The Dashboard shows whether each metric is within regulatory limits.

Sheet Illust - Periodic & Cumul Gap
A1: ILLUSTRATION: PERIODIC GAP vs CUMULATIVE GAP
A3: CONCEPT
A4: Periodic Gap: | B4: The gap for ONE specific time bucket. It answers: "In THIS period alone, do I have more assets or liabilities maturing?"
A5: Cumulative Gap: | B5: The running total of ALL periodic gaps from the start. It answers: "FROM NOW until this point, what is my TOTAL net funding position?"
A6: Why both matter: | B6: A bucket may have a positive periodic gap, but the cumulative gap could still be negative if earlier deficits haven't been offset yet.
A8: STEP-BY-STEP EXAMPLE (Using the Mini Bank from Structural Liquidity tab)
A9: Step 1: Start with the periodic gaps (from Structural Liquidity)
B10: 0-3M | C10: 3-12M | D10: 1-5Y | E10: >5Y
A11: Assets Maturing | B11: 100 | C11: 150 | D11: 400 | E11: 350
A12: Liabilities Maturing | B12: 350 | C12: 350 | D12: 100 | E12: 200
A13: Periodic Gap (A – L) | B13: =B11-B12 -> -250 | C13: =C11-C12 -> -200 | D13: =D11-D12 -> 300 | E13: =E11-E12 -> 150
A15: Step 2: Build the CUMULATIVE gap (running total)
B16: 0-3M | C16: 3-12M | D16: 1-5Y | E16: >5Y
A17: Periodic Gap (this bucket only) | B17: =B13 -> -250 | C17: =C13 -> -200 | D17: =D13 -> 300 | E17: =E13 -> 150
A18: Formula: | B18: = ($250) | C18: = ($250) + ($200) | D18: = ($450) + $300 | E18: = ($150) + $150
A19: → CUMULATIVE GAP | B19: =B17 -> -250 | C19: =B19+C17 -> -450 | D19: =C19+D17 -> -150 | E19: =D19+E17 -> 0
A21: Step 3: Walk through each bucket — Periodic vs Cumulative side by side
A22: Bucket | B22: Periodic Gap | C22: Cumulative Gap | D22: What’s happening? | E22: Action needed?
A23: 0-3 Months | B23: =B13 -> -250 | C23: =B19 -> -250 | D23: More deposits & borrowings due than assets maturing. Immediate funding pressure. | E23: ❌ YES — Must raise $250 via new deposits, interbank loans, or sell liquid assets.
A24: 3-12 Months | B24: =C13 -> -200 | C24: =C19 -> -450 | D24: Another deficit period. Even though periodic gap is ($200), the cumulative gap is ($450) because the prior $250 deficit carries forward. | E24: ❌ YES — Cumulative $450 deficit. Bank has been in continuous funding shortfall for 12 months.
A25: 1-5 Years | B25: =D13 -> 300 | C25: =D19 -> -150 | D25: Large SURPLUS this period ($300). Loan repayments exceed maturing deposits. But cumulative is STILL negative ($150) because prior deficits haven’t been fully offset. | E25: ⚠️ PARTIAL — Periodic surplus helps, but cumulative gap still negative. Not fully recovered.
A26: >5 Years | B26: =E13 -> 150 | C26: =E19 -> 0 | D26: Another surplus ($150). Cumulative gap reaches $0 — over the FULL life of the balance sheet, total assets = total liabilities + equity. | E26: ✅ BALANCED — Over total horizon, balance sheet is square. But the PATH matters more than the endpoint.
A28: KEY INSIGHT: WHY CUMULATIVE GAP MATTERS MORE
A29: Analogy: | B29: Think of it like a bank account. The periodic gap is your income minus expenses each month. The cumulative gap is your running balance. Even if you earn more than you spend in Month 3 (+$300), your balance could still be negative if you overspent in Months 1 & 2.
A30: The trap: | B30: Looking ONLY at periodic gaps can be misleading. The 1-5Y bucket shows a healthy +$300 surplus, but the cumulative position is STILL ($150) in deficit. A bank manager looking only at the periodic gap might feel comfortable, but the cumulative view reveals ongoing funding stress.
A31: Regulatory focus: | B31: RBI and Basel III focus on CUMULATIVE gap metrics, not periodic. The key limit is: Cumulative Gap within 1 Year / Total Assets should be > -15%. In this mini example: ($450) / $1,000 = -45% — a severe breach! This bank needs urgent funding action.
A32: Your Model: | B32: The actual bank in this model has a cumulative 1-year gap of ($6,100mm) / $95,000mm = -6.4%, which is within the -15% threshold. See ‘Liquidity Gap’ Row 22 and ‘Dashboard’ B8.

Sheet Illust - Liquidity Ratios
A1: ILLUSTRATION: LIQUIDITY GAP RATIOS
A3: WHY RATIOS? Raw dollar gaps don’t tell you how serious the mismatch is. A ($250) gap is critical for a $1,000 bank but trivial for a $1,000,000 bank. Ratios normalize the gaps for comparison.
A5: THREE KEY RATIOS (Using Mini Bank: Total Assets = $1,000)
A7: RATIO 1: Gap as % of Total Assets
A8: Formula: | B8: = Periodic Gap in Bucket ÷ Total Assets
A9: Purpose: | B9: Shows how large each bucket’s mismatch is relative to the bank’s entire balance sheet. Makes gaps comparable across banks of different sizes.
B11: 0-3M | C11: 3-12M | D11: 1-5Y | E11: >5Y | F11: Threshold
A12: Periodic Gap ($) | B12: -250 | C12: -200 | D12: 300 | E12: 150
A13: Total Assets ($) | B13: 1000 | C13: 1000 | D13: 1000 | E13: 1000
A14: → Gap / Total Assets | B14: =B12/B13 -> -0.25 | C14: =C12/C13 -> -0.2 | D14: =D12/D13 -> 0.3 | E14: =E12/E13 -> 0.15 | F14: Within ±10%
A15: Reading: | B15: -25%: A quarter of the bank’s balance sheet is exposed to a short-term funding gap. This is a SEVERE mismatch — far beyond the ±10% comfort zone.
A17: RATIO 2: Cumulative Gap as % of Total Assets (THE KEY REGULATORY METRIC)
A18: Formula: | B18: = Cumulative Gap at Bucket ÷ Total Assets
A19: Purpose: | B19: Shows the bank’s total accumulated mismatch as a share of balance sheet. THIS is what regulators watch most closely.
B21: 0-3M | C21: 3-12M | D21: 1-5Y | E21: >5Y | F21: Threshold
A22: Cumulative Gap ($) | B22: -250 | C22: -450 | D22: -150 | E22: 0
A23: Total Assets ($) | B23: 1000 | C23: 1000 | D23: 1000 | E23: 1000
A24: → Cumul Gap / Total Assets | B24: =B22/B23 -> -0.25 | C24: =C22/C23 -> -0.45 | D24: =D22/D23 -> -0.15 | E24: =E22/E23 -> 0 | F24: > -15%
A25: Reading: | B25: At 3-12M, the cumulative gap hits -45% of total assets — a massive breach of the -15% limit. This mini bank is dangerously over-reliant on short-term funding. Your actual model shows -6.4% (PASS).
A27: RATIO 3: Gap as % of Total Outflows
A28: Formula: | B28: = Periodic Gap ÷ Total Liabilities Maturing in Bucket
A29: Purpose: | B29: Shows what FRACTION of outflows in each bucket is uncovered by maturing assets. This tells you the severity of funding pressure in each specific period.
B31: 0-3M | C31: 3-12M | D31: 1-5Y | E31: >5Y
A32: Periodic Gap ($) | B32: -250 | C32: -200 | D32: 300 | E32: 150
A33: Liabilities Maturing ($) | B33: 350 | C33: 350 | D33: 100 | E33: 200
A34: → Gap / Outflows | B34: =B32/B33 -> -0.71428571 | C34: =C32/C33 -> -0.57142857 | D34: =D32/D33 -> 3 | E34: =E32/E33 -> 0.75
A35: Reading: | B35: 0-3M: -71.4% means 71% of short-term outflows are UNCOVERED. For every $1 in maturing liabilities, only $0.29 in maturing assets. The bank must find external funding for the other $0.71. A healthy target is > -30%.
A37: SUMMARY: ALL THREE RATIOS AT A GLANCE
A38: Ratio | B38: What it measures | C38: Mini Bank | D38: Your Model | E38: Threshold | F38: Verdict
A39: Gap / Total Assets (short-term) | B39: Size of mismatch vs. balance sheet | C39: -0.25 | D39: =Dashboard!B7 -> -0.046315789 | E39: > -10% | F39: ❌ Mini / ✅ Model
A40: Cumul Gap / Total Assets (1Y) | B40: Accumulated mismatch over 1 year | C40: -0.45 | D40: =Dashboard!B8 -> -0.064210526 | E40: > -15% | F40: ❌ Mini / ✅ Model
A41: Gap / Outflows (short-term) | B41: % of outflows not covered by maturing assets | C41: -0.714 | D41: See Liquidity Gap sheet | E41: > -30% | F41: ❌ Mini / varies

Sheet Illust - RSA vs RSL
A1: ILLUSTRATION: RATE-SENSITIVE ASSETS (RSA) vs RATE-SENSITIVE LIABILITIES (RSL)
A3: CONCEPT
A4: RSA: | B4: Assets whose INTEREST INCOME will change when market rates change — either because they carry a floating rate (reprices periodically) or because they mature soon and will be reinvested at the new market rate.
A5: RSL: | B5: Liabilities whose INTEREST COST will change when rates change — same logic: floating rate or maturing soon and will be rolled at new rates.
A6: The Gap: | B6: Rate Gap = RSA – RSL. If POSITIVE → bank is ASSET-SENSITIVE (benefits from rising rates). If NEGATIVE → bank is LIABILITY-SENSITIVE (benefits from falling rates).
A8: STEP 1: HOW TO CLASSIFY — Which items are "rate-sensitive"?
A9: Item | B9: Rate Sensitive? | C9: Why? | D9: Classified by:
A10: Floating-Rate Loan @ SOFR+2% | B10: ✅ YES | C10: Rate resets every quarter when SOFR changes | D10: REPRICING date (next reset)
A11: Fixed-Rate Loan @ 8.75% | B11: ✅ YES | C11: Rate is fixed, BUT when it matures, the proceeds are reinvested at the new market rate | D11: MATURITY date (when it matures)
A12: Demand Deposit (Savings Acct) | B12: ✅ YES | C12: Bank can change the rate at discretion in response to market | D12: BEHAVIORAL model (assumed run-off)
A13: Shareholders’ Equity | B13: ❌ NO | C13: Has no interest cost — it’s permanent capital, not a borrowing | D13: N/A — excluded from RSL
A14: Fixed Assets (Buildings) | B14: ❌ NO | C14: Non-interest-bearing. A building doesn’t earn/pay interest | D14: N/A — excluded from RSA
A16: STEP 2: WORKED EXAMPLE — Mini Bank Rate Sensitivity
A17: RSA (within 1 year) | B17: Amount | C17: Current Rate | D17: Interest Income
A18: Floating-Rate Loans (reprice quarterly) | B18: 300 | C18: 0.08 | D18: =B18*C18 -> 24
A19: Maturing Fixed Bonds (due in 6M) | B19: 150 | C19: 0.06 | D19: =B19*C19 -> 9
A20: Cash (overnight rate) | B20: 100 | C20: 0.04 | D20: =B20*C20 -> 4
A21: → TOTAL RSA | B21: =SUM(B18:B20) -> 550 | D21: =SUM(D18:D20) -> 37
A23: RSL (within 1 year) | B23: Amount | C23: Current Rate | D23: Interest Expense
A24: Demand Deposits (discretionary repricing) | B24: 250 | C24: 0.03 | D24: =B24*C24 -> 7.5
A25: Maturing Term Deposits (due in 9M) | B25: 100 | C25: 0.055 | D25: =B25*C25 -> 5.5
A26: → TOTAL RSL | B26: =SUM(B24:B25) -> 350 | D26: =SUM(D24:D25) -> 13
A28: KEY METRICS:
A29: Rate Gap (RSA – RSL): | B29: =B21-B26 -> 200 | C29: ← Positive = ASSET-SENSITIVE
A30: RSA / RSL Ratio: | B30: =B21/B26 -> 1.5714286 | C30: ← Above 1.0x = more assets reprice than liabilities
A31: Base NII: | B31: =D21-D26 -> 24 | C31: ← Interest Income – Interest Expense
A33: STEP 3: WHAT HAPPENS WHEN RATES CHANGE? (+100 bps = +1.00%)
B34: BASE CASE | C34: +100 bps | D34: Change | E34: Logic
A35: Interest Income (RSA) | B35: =D21 -> 37 | C35: =B18*(C18+0.01)+B19*(C19+0.01)+B20*(C20+0.01) -> 42.5 | D35: =C35-B35 -> 5.5 | E35: All $550 in RSA earns 1% more → +$5.5 income
A36: Interest Expense (RSL) | B36: =D26 -> 13 | C36: =B24*(C24+0.01)+B25*(C25+0.01) -> 16.5 | D36: =C36-B36 -> 3.5 | E36: All $350 in RSL costs 1% more → +$3.5 expense
A37: → NET INTEREST INCOME | B37: =B35-B36 -> 24 | C37: =C35-C36 -> 26 | D37: =C37-B37 -> 2 | E37: ← NII INCREASED by $2.0 because RSA > RSL
A39: Verify: | B39: ΔNII = Rate Gap × Rate Change | C39: =B29*0.01 -> 2 | D39: ← $200 gap × 1% = $2.0 ✔️
A41: THE TAKEAWAY
A42: Asset-Sensitive (RSA > RSL): | B42: Rate ↑ → Income rises MORE than costs → NII INCREASES ✅ Rate ↓ → Income falls MORE than costs → NII DECREASES ❌
A43: Liability-Sensitive (RSL > RSA): | B43: Rate ↑ → Costs rise MORE than income → NII DECREASES ❌ Rate ↓ → Costs fall MORE than income → NII INCREASES ✅
A44: Your Model: | B44: RSA/RSL = 1.06x (slightly asset-sensitive). The bank’s NII benefits from rate increases. See ‘Rate Sensitivity Gap’ Row 22 and ‘Dashboard’ B9.

Sheet Illust - Fixed vs Floating
A1: ILLUSTRATION: FIXED RATE vs FLOATING RATE ANALYSIS
A3: CONCEPT: THE FIXED-FLOATING SPLIT DETERMINES HOW FAST YOUR INCOME/COST REACTS TO RATE CHANGES
A5: Feature | B5: FIXED RATE | C5: FLOATING RATE
A6: How rate is set | B6: Locked at origination for the full term (e.g., 8.75% for 5 years) | C6: Benchmark + spread, resets periodically (e.g., SOFR + 2%, resets quarterly)
A7: When does rate change? | B7: ONLY at maturity when the asset/liability is renewed at new market rate | C7: At each REPRICING DATE (monthly, quarterly, semi-annually) regardless of maturity
A8: Rate risk exposure | B8: LOW in near-term (rate locked) but HIGH at renewal (entire amount reprices at once) | C8: HIGH continuously (rate moves with market) but PREDICTABLE (spread is locked)
A9: Time bucket placement | B9: Placed in bucket matching CONTRACTUAL MATURITY → a 5-year fixed loan goes in "3-5Y" bucket | C9: Placed in bucket matching NEXT REPRICING DATE → a 20-year floating loan repricing quarterly goes in "29D-3M"
A10: Example | B10: $100 loan at 8.75% fixed for 3 years → earns $8.75/yr regardless of rate changes for 3 years | C10: $100 loan at SOFR+2% → if SOFR rises from 5% to 6%, income jumps from $7/yr to $8/yr in next quarter
A12: WORKED EXAMPLE: Two Identical $500 Loan Portfolios — Fixed vs Floating
A13: Setup: | B13: Both banks have $500 in loans funded by $400 in deposits (rate = 3%) + $100 equity. Only the LOAN TYPE differs.
B15: BANK A: 100% Fixed | C15: BANK B: 100% Floating | D15: BANK C: 50/50 Mix
A16: Loan Rate (initial) | B16: 8.00% fixed (5-year) | C16: SOFR+2% = 7.00% | D16: 8.00% fixed / 7.00% float
A17: Deposit Rate | B17: 0.03 | C17: 0.03 | D17: 0.03
A19: SCENARIO: Market rates RISE +200 bps (+2.00%)
B20: Bank A (Fixed) | C20: Bank B (Floating) | D20: Bank C (50/50) | E20: Why?
A21: Loan Income (before) | B21: 40 | C21: 35 | D21: 37.5
A22: Loan Income (after +200bps) | B22: 40 | C22: 45 | D22: 42.5 | E22: Fixed stays at 8%; Floating reprices to 9%
A23: Deposit Cost (after, assume +100bps pass-through) | B23: 16 | C23: 16 | D23: 16 | E23: Deposits reprice from 3% to 4% (partial pass-through)
A24: → NEW NII | B24: =B22-B23 -> 24 | C24: =C22-C23 -> 29 | D24: =D22-D23 -> 26.5
A25: Original NII | B25: =B21-12 -> 28 | C25: =C21-12 -> 23 | D25: =D21-12 -> 25.5
A26: Δ NII (Change) | B26: =B24-B25 -> -4 | C26: =C24-C25 -> 6 | D26: =D24-D25 -> 1
A28: INTERPRETATION
A29: Bank A (100% Fixed): | B29: NII DECREASED by $4 when rates rose. Why? The fixed loan rate (8%) cannot increase, but deposit costs rose from 3% to 4%. The bank’s income is LOCKED while its costs are rising. Fixed-rate assets act like a LIABILITY-SENSITIVE position.
A30: Bank B (100% Floating): | B30: NII INCREASED by $6 when rates rose. Why? Floating loans repriced from 7% to 9% (+$10 income), while deposits only rose from 3% to 4% (+$4 cost). The ASYMMETRIC repricing creates a net benefit. More floating assets = more asset-sensitivity.
A31: Bank C (50/50 Mix): | B31: NII INCREASED by $1 — a moderate benefit. The floating half captured the rate increase while the fixed half provided stability. This is the most common real-world approach: banks maintain a MIX to balance rate sensitivity and earnings stability.
A33: KEY TAKEAWAYS
A34: 1. The fixed/floating MIX directly determines rate sensitivity | B34: More floating assets → faster repricing → more sensitive to rate changes. More fixed assets → slower repricing → earnings more stable but miss opportunities.
A35: 2. It’s about ASYMMETRY between asset and liability repricing | B35: The risk isn’t that rates change — it’s that assets and liabilities reprice at DIFFERENT speeds. If both sides were 100% floating, NII would barely move.
A36: 3. Banks use swaps to manage the mix synthetically | B36: Rather than originating only one type, banks can use Interest Rate Swaps to convert fixed to floating (or vice versa). Pay-fixed/receive-floating swap converts a floating asset into a synthetic fixed asset.
A37: Your Model: | B37: Assets: $28B floating + $27B fixed (roughly 50/50). Liabilities: CASA (discretionary) + term deposits (fixed) + borrowings (floating). The net result is slightly asset-sensitive (RSA/RSL = 1.06x). See ‘Assumptions’ B26:B30 for rate details and ‘Rate Sensitivity Gap’ for the full repricing profile.

Sheet Illust - NII & NIM
A1: ILLUSTRATION: NET INTEREST INCOME (NII) & NET INTEREST MARGIN (NIM)
A3: KEY DEFINITIONS
A4: NII: | B4: Net Interest Income = Total Interest Income – Total Interest Expense. This is the bank’s PRIMARY revenue driver (typically 60-80% of total income). It represents the “spread” the bank earns between what it charges borrowers and what it pays depositors.
A5: NIM: | B5: Net Interest Margin = NII ÷ Total Interest-Earning Assets. Expressed as a percentage, it measures the efficiency of the bank’s interest-earning operations. It is the single most-watched profitability metric for banks.
A6: NII at Risk: | B6: The potential CHANGE in NII under a hypothetical interest rate shock. This is the earnings-based measure of interest rate risk. Formula: ΔNII = Cumulative 1-Year Rate Gap × Rate Change (bps/10000).
A8: STEP 1: CALCULATE BASE NII (Mini Bank Example, $1,000 Total Assets)
A9: INTEREST-EARNING ASSETS | B9: Balance ($) | C9: Rate | D9: Annual Interest | E9: Calculation
A10: Cash & Central Bank Balances | B10: 100 | C10: 0.04 | D10: =B10*C10 -> 4 | E10: $100 × 4.00% = $4.0
A11: Government Securities | B11: 200 | C11: 0.065 | D11: =B11*C11 -> 13 | E11: $200 × 6.50% = $13.0
A12: Loans & Advances | B12: 600 | C12: 0.085 | D12: =B12*C12 -> 51 | E12: $600 × 8.50% = $51.0
A13: Interbank Placements | B13: 50 | C13: 0.055 | D13: =B13*C13 -> 2.75 | E13: $50 × 5.50% = $2.8
A14: (Non-earning: Fixed Assets $50, not included)
A15: → TOTAL INTEREST INCOME | B15: =SUM(B10:B13) -> 950 | C15: =D15/B15 -> 0.074473684 | D15: =SUM(D10:D13) -> 70.75 | E15: Weighted avg asset yield = 7.44%
A17: INTEREST-BEARING LIABILITIES | B17: Balance ($) | C17: Rate | D17: Annual Interest | E17: Calculation
A18: Demand Deposits (CASA) | B18: 300 | C18: 0.035 | D18: =B18*C18 -> 10.5 | E18: $300 × 3.50% = $10.5
A19: Term Deposits | B19: 350 | C19: 0.065 | D19: =B19*C19 -> 22.75 | E19: $350 × 6.50% = $22.8
A20: Interbank Borrowings | B20: 150 | C20: 0.058 | D20: =B20*C20 -> 8.7 | E20: $150 × 5.80% = $8.7
A21: (Non-bearing: Equity $200, not included)
A22: → TOTAL INTEREST EXPENSE | B22: =SUM(B18:B20) -> 800 | C22: =D22/B22 -> 0.0524375 | D22: =SUM(D18:D20) -> 41.95 | E22: Weighted avg funding cost = 5.25%
A24: STEP 2: CALCULATE NII AND NIM
A25: Metric | B25: Formula | C25: Calculation | D25: Result | E25: Meaning
A26: Net Interest Income (NII) | B26: Interest Income – Interest Expense | C26: $70.8 – $42.0 | D26: =D15-D22 -> 28.8 | E26: The bank earns $28.8 in NET interest annually after paying all depositors and lenders.
A27: Net Interest Margin (NIM) | B27: NII ÷ Interest-Earning Assets | C27: $28.8 ÷ $950 | D27: =D26/B15 -> 0.030315789 | E27: For every $100 in earning assets, the bank earns $3.03 in net interest.
